<?xml version="1.0" encoding="UTF-8"?>
<!-- Generated by org.testng.reporters.JUnitReportReporter -->
<testsuite hostname="MSI" failures="1" tests="5" name="TestNGstudy.FailedTCExecution" time="0.130" errors="1" timestamp="2022-11-16T17:50:12 IST" skipped="0">
  <testcase classname="TestNGstudy.FailedTCExecution" name="TC7" time="0.001"/>
  <system-out>
    <![CDATA[TC7 Running]]>
  </system-out>
  <testcase classname="TestNGstudy.FailedTCExecution" name="TC10" time="0.009"/>
  <system-out>
    <![CDATA[TC10 Running]]>
  </system-out>
  <testcase classname="TestNGstudy.FailedTCExecution" name="TC6" time="0.106">
    <error message="Method TestNGstudy.FailedTCExecution.TC6() didn&#039;t finish within the time-out 100" type="org.testng.internal.thread.ThreadTimeoutException">
      <![CDATA[org.testng.internal.thread.ThreadTimeoutException: Method TestNGstudy.FailedTCExecution.TC6() didn't finish within the time-out 100
at org.testng.internal.MethodInvocationHelper.invokeWithTimeoutWithNewExecutor(MethodInvocationHelper.java:384)
at org.testng.internal.MethodInvocationHelper.invokeWithTimeout(MethodInvocationHelper.java:283)
at org.testng.internal.TestInvoker.invokeMethod(TestInvoker.java:604)
at org.testng.internal.TestInvoker.invokeTestMethod(TestInvoker.java:173)
at org.testng.internal.MethodRunner.runInSequence(MethodRunner.java:46)
at org.testng.internal.TestInvoker$MethodInvocationAgent.invoke(TestInvoker.java:824)
at org.testng.internal.TestInvoker.invokeTestMethods(TestInvoker.java:146)
at org.testng.internal.TestMethodWorker.invokeTestMethods(TestMethodWorker.java:146)
at org.testng.internal.TestMethodWorker.run(TestMethodWorker.java:128)
at java.base/java.util.ArrayList.forEach(ArrayList.java:1511)
at org.testng.TestRunner.privateRun(TestRunner.java:794)
at org.testng.TestRunner.run(TestRunner.java:596)
at org.testng.SuiteRunner.runTest(SuiteRunner.java:377)
at org.testng.SuiteRunner.runSequentially(SuiteRunner.java:371)
at org.testng.SuiteRunner.privateRun(SuiteRunner.java:332)
at org.testng.SuiteRunner.run(SuiteRunner.java:276)
at org.testng.SuiteRunnerWorker.runSuite(SuiteRunnerWorker.java:53)
at org.testng.SuiteRunnerWorker.run(SuiteRunnerWorker.java:96)
at org.testng.TestNG.runSuitesSequentially(TestNG.java:1212)
at org.testng.TestNG.runSuitesLocally(TestNG.java:1134)
at org.testng.TestNG.runSuites(TestNG.java:1063)
at org.testng.TestNG.run(TestNG.java:1031)
at org.testng.remote.AbstractRemoteTestNG.run(AbstractRemoteTestNG.java:115)
at org.testng.remote.RemoteTestNG.initAndRun(RemoteTestNG.java:251)
at org.testng.remote.RemoteTestNG.main(RemoteTestNG.java:77)
]]>
    </error>
  </testcase> <!-- TC6 -->
  <system-out>
    <![CDATA[TC6 Running]]>
  </system-out>
  <testcase classname="TestNGstudy.FailedTCExecution" name="TC8" time="0.013">
    <failure message="The following asserts failed:
	null" type="java.lang.AssertionError">
      <![CDATA[java.lang.AssertionError: The following asserts failed:
null
at org.testng.asserts.SoftAssert.assertAll(SoftAssert.java:47)
at org.testng.asserts.SoftAssert.assertAll(SoftAssert.java:31)
at TestNGstudy.FailedTCExecution.TC8(FailedTCExecution.java:37)
at java.base/jdk.internal.reflect.DirectMethodHandleAccessor.invoke(DirectMethodHandleAccessor.java:104)
at java.base/java.lang.reflect.Method.invoke(Method.java:577)
at org.testng.internal.MethodInvocationHelper.invokeMethod(MethodInvocationHelper.java:133)
at org.testng.internal.TestInvoker.invokeMethod(TestInvoker.java:598)
at org.testng.internal.TestInvoker.invokeTestMethod(TestInvoker.java:173)
at org.testng.internal.MethodRunner.runInSequence(MethodRunner.java:46)
at org.testng.internal.TestInvoker$MethodInvocationAgent.invoke(TestInvoker.java:824)
at org.testng.internal.TestInvoker.invokeTestMethods(TestInvoker.java:146)
at org.testng.internal.TestMethodWorker.invokeTestMethods(TestMethodWorker.java:146)
at org.testng.internal.TestMethodWorker.run(TestMethodWorker.java:128)
at java.base/java.util.ArrayList.forEach(ArrayList.java:1511)
at org.testng.TestRunner.privateRun(TestRunner.java:794)
at org.testng.TestRunner.run(TestRunner.java:596)
at org.testng.SuiteRunner.runTest(SuiteRunner.java:377)
at org.testng.SuiteRunner.runSequentially(SuiteRunner.java:371)
at org.testng.SuiteRunner.privateRun(SuiteRunner.java:332)
at org.testng.SuiteRunner.run(SuiteRunner.java:276)
at org.testng.SuiteRunnerWorker.runSuite(SuiteRunnerWorker.java:53)
at org.testng.SuiteRunnerWorker.run(SuiteRunnerWorker.java:96)
at org.testng.TestNG.runSuitesSequentially(TestNG.java:1212)
at org.testng.TestNG.runSuitesLocally(TestNG.java:1134)
at org.testng.TestNG.runSuites(TestNG.java:1063)
at org.testng.TestNG.run(TestNG.java:1031)
at org.testng.remote.AbstractRemoteTestNG.run(AbstractRemoteTestNG.java:115)
at org.testng.remote.RemoteTestNG.initAndRun(RemoteTestNG.java:251)
at org.testng.remote.RemoteTestNG.main(RemoteTestNG.java:77)
]]>
    </failure>
  </testcase> <!-- TC8 -->
  <system-out>
    <![CDATA[TC8 Running]]>
  </system-out>
  <testcase classname="TestNGstudy.FailedTCExecution" name="TC9" time="0.001"/>
  <system-out>
    <![CDATA[TC9 Running]]>
  </system-out>
</testsuite> <!-- TestNGstudy.FailedTCExecution -->
